Workbook

Sheet env data
A2: Date | B2: Waterbody | C2: Waterbody.edit | D2: Phycocyanin WHW | E2: Phycocyanin >50 | F2: Phycocyanin BFC | G2: Chlorophyll WHW | H2: Chlorophyll >50 | I2: Chlorophyll BFC | J2: Particles/ML | K2: Cyanobacteria Density | L2: Dominance | M2: Notes
A3: 45045 | B3: Bell Pond | C3: Bell | D3: 2.351 | E3: 1.2806667 | G3: 6.1632222 | H3: 6.7832222 | J3: 4.41 | K3: none | L3: none
A4: 45045 | B4: Burncoat Pond | C4: Burncoat | D4: 16.543222 | E4: 16.948778 | F4: 84.017667 | G4: 97.937 | H4: 97.065889 | I4: 139.77367 | J4: 498.35 | K4: low | L4: Dolichospermum (10%), Microcystis (90%)
A5: 45045 | B5: Coes Pond | C5: Coes.P | J5: NA | K5: NA | L5: NA
A6: 45045 | B6: Coes Reservoir | C6: Coes.R | D6: 4.8445556 | E6: 2.9892222 | G6: 17.657 | H6: 12.182667 | J6: 68.97 | K6: none | L6: none
A7: 45045 | B7: Cooks Pond | C7: Crooks | D7: -0.11555556 | E7: 3.5223333 | F7: -2.648 | G7: 15.419111 | H7: 14.596889 | I7: 14.088 | J7: 38.53 | K7: none | L7: none
A8: 45045 | B8: Crystal Pond | C8: Crystal | D8: 19.541 | E8: 12.456556 | F8: 18.734333 | G8: 26.882889 | H8: 20.194 | I8: 48.777333 | J8: 568.21 | K8: none | L8: none
A9: 45045 | B9: Curtis Pond | C9: Curtis | D9: 0 | E9: 0 | F9: 0 | G9: 0 | H9: 0 | I9: 0 | J9: 0 | K9: NA | L9: 0
A10: 45045 | B10: Dark Brook Reservoir | C10: Dark.Brook | J10: NA | K10: NA | L10: NA
A11: 45045 | B11: East Lake Waushacum | C11: E.Waushacum | J11: NA | K11: NA | L11: NA
A12: 45045 | B12: Ecotarium Pond | C12: Ecotarium | J12: NA | K12: NA | L12: NA
A13: 45045 | B13: Elm Park Pond | C13: Elm | J13: NA | K13: NA | L13: NA
A14: 45045 | B14: Farm Pond | C14: Farm | D14: 0.50477778 | E14: 2.2221111 | F14: 3.644 | G14: 3.7483333 | H14: 4.4795556 | I14: 5.2653333 | J14: 12.94 | K14: none | L14: none
A15: 45045 | B15: Flint Pond | C15: Flint | J15: NA | K15: NA | L15: NA
A16: 45045 | B16: Green Hill Park Pond | C16: Green.Hill | D16: -0.145 | E16: 0.136 | G16: 11.339778 | H16: 9.7204444 | J16: 25.03 | K16: none | L16: none
A17: 45045 | B17: Indian Lake | C17: Indian | D17: 4.043 | E17: 3.402 | G17: 16.357 | H17: 14.124778 | J17: 213.1 | K17: low | L17: Microcystis (20%), Microcystis Debris (80%)
A18: 45045 | B18: Jordan Pond | C18: Jordan | D18: 5.1678889 | E18: 3.3727778 | F18: 5.6776667 | G18: 7.1325556 | H18: 5.5807778 | I18: 13.914667 | J18: 24.96 | K18: none | L18: none
A19: 45045 | B19: Kiver Pond | C19: Kiver | D19: 23.033556 | E19: 3.635 | G19: 109.57656 | H19: 11.813222 | J19: 157.53 | K19: low | L19: Microcystis (100%)
A20: 45045 | B20: Lake Chauncy | C20: Chauncy | D20: 7.2714444 | E20: 7.4481111 | G20: 10.384667 | H20: 12.619333 | J20: 12.05 | K20: low | L20: Aphanizomenon (100%)
A21: 45045 | B21: Lake Lashaway | C21: Lashaway | D21: 4.6396667 | E21: 3.1977778 | F21: 81.184333 | G21: 13.376889 | H21: 11.408 | I21: 26.341333 | J21: 28.99 | K21: low | L21: Microcystis Debris (100%)
A22: 45045 | B22: Lake Quinsigamond | C22: Quinsigamond | D22: 1.2874444 | E22: 1.0801111 | G22: 12.117444 | H22: 8.7236667 | J22: 20.95 | K22: none | L22: none
A23: 45045 | B23: Leeseville Pond | C23: Leesville | D23: 13.050333 | E23: 6.7688889 | G23: 21.133333 | H23: 9.3672222 | J23: 126.95 | K23: none | L23: none
A24: 45045 | B24: Little Indian Lake | C24: L.Indian | D24: 2.9737778 | E24: 2.3368889 | G24: 36.066889 | H24: 36.086889 | J24: 226.86 | K24: low | L24: Dolichospermum (100%)
A25: 45045 | B25: Manchaug Pond | C25: Manchaug | D25: 0.38366667 | E25: 0.25822222 | F25: 48.568333 | G25: 8.5146667 | H25: 8.6663333 | I25: 40.779667 | J25: 48.33 | K25: none | L25: none
A26: 45045 | B26: Newton Pond | C26: Newton | D26: -1.504 | E26: -0.042555556 | G26: 3.6343333 | H26: 3.8885556 | J26: 26.74 | K26: none | L26: none
A27: 45045 | B27: Patch Pond | C27: Patch.P | D27: 9.476 | E27: 3.7788889 | F27: 233.013 | G27: 12.857667 | H27: 8.9465556 | I27: 136.79433 | J27: 75.8 | K27: none | L27: none
A28: 45045 | B28: Patch Reservoir | C28: Patch.R | D28: 0.35877778 | E28: -1.3498889 | G28: 7.6188889 | H28: 5.9623333 | J28: 57.23 | K28: low | L28: Microcystis (100%)
A29: 45045 | B29: Salisbury Pond | C29: Salisbury | D29: 4.6283333 | E29: 7.218 | F29: 6.0253333 | G29: 21.621889 | H29: 20.903 | I29: 18.153 | J29: 191.33 | K29: low | L29: Microcystis (90%), Microcystis Debris (10%)
A30: 45045 | B30: Singletary Lake | C30: Singletary | J30: NA | K30: NA | L30: NA
A31: 45045 | B31: Stevens Pond | C31: Stevens | D31: -0.41922222 | E31: -1.9695556 | G31: 4.4735556 | H31: 3.2982222 | J31: 30.12 | K31: none | L31: none
A32: 45045 | B32: Stoneville Pond | C32: Stoneville | J32: NA | K32: NA | L32: NA
A33: 45061 | B33: Bell Pond | C33: Bell | D33: 1.0301111 | E33: 3.3594444 | G33: 2.4355556 | H33: 2.5507778 | J33: 57 | K33: none | L33: none
A34: 45061 | B34: Burncoat Pond | C34: Burncoat | D34: 48.904444 | E34: 32.347778 | G34: 204.06389 | H34: 170.49722 | J34: 561 | K34: none | L34: none
A35: 45061 | B35: Coes Pond | C35: Coes.P | J35: NA | K35: NA | L35: NA
A36: 45061 | B36: Coes Reservoir | C36: Coes.R | D36: 1.4857778 | E36: -0.28333333 | G36: 8.8126667 | H36: 7.665 | J36: 105 | K36: low | L36: Dolichospermum (100%)
A37: 45061 | B37: Cooks Pond | C37: Crooks | D37: -0.97066667 | E37: 0.26377778 | G37: 12.330333 | H37: 12.855889 | J37: 42 | K37: none | L37: none
A38: 45061 | B38: Crystal Pond | C38: Crystal | D38: 7.9986667 | E38: 13.325333 | G38: 26.072333 | H38: 26.945667 | J38: 652 | K38: none | L38: none
A39: 45061 | B39: Curtis Pond | C39: Curtis | D39: 1.9157778 | E39: 3.2421111 | G39: 15.705889 | H39: 23.688111 | J39: 383 | K39: low | L39: Dolichospermum (10%), Microcystis (10%), Microcystis Debris (80%)
A40: 45061 | B40: Dark Brook Reservoir | C40: Dark.Brook | J40: NA | K40: NA | L40: NA
A41: 45061 | B41: East Lake Waushacum | C41: E.Waushacum | D41: -2.6191111 | E41: 0.090666667 | G41: 4.9136667 | H41: 4.4601111 | J41: 44 | K41: none | L41: none
...

Sheet cyano dominance
J1: =COUNTA(J4:J392)-COUNTIF(J4:J392,"NA") -> 45 | K1: =COUNTA(K4:K392)-COUNTIF(K4:K392,"NA") -> 107 | L1: =COUNTA(L4:L392)-COUNTIF(L4:L392,"NA") -> 41 | M1: =COUNTA(M4:M392)-COUNTIF(M4:M392,"NA") -> 52 | N1: =COUNTA(N4:N392)-COUNTIF(N4:N392,"NA") -> 9 | O1: =COUNTA(O4:O392)-COUNTIF(O4:O392,"NA") -> 28 | Y1: NA.count | Z1: abund in one
Y2: =COUNTIF(P4:P392,6) -> 0 | Z2: =COUNTA(P4:P392)-Y2 -> 389
A3: Index | B3: Date | C3: Waterbody | D3: Waterbody.edit | E3: Dominance | F3: Date | G3: Waterbody | H3: Waterbody.edit | I3: Dominance | J3: Aphanizomenon | K3: Dolichospermum | L3: Microcystis | M3: Microcystis_Debris | N3: Oscillatoria | O3: Woronichinia | P3: NA.count | Q3: Aph.check | R3: Micro.check | S3: Osc.check | T3: Wor.check | U3: sum.checks
A4: 198 | B4: 45145 | C4: Lake Chauncy | D4: Chauncy | E4: Aphanizomenon (10%), Dolichospermum (60%), Microcystis (10%), Microcystis Debris (20%), Woronichinia (0%) | F4: 45145 | G4: Lake Chauncy | H4: Chauncy | I4: Aphanizomenon (10%), Dolichospermum (60%), Microcystis (10%), Microcystis Debris (20%), Woronichinia (0%) | J4: 10 | K4: 60 | L4: 10 | M4: 20 | N4: NA | O4: 0 | P4: =COUNTA(J4:O4)-COUNTIF(J4:O4,"NA") -> 5 | Q4: =IF(NOT(J4="NA"),1,"NA") -> 1 | R4: =IF(NOT(L4="NA"),1,"NA") -> 1 | S4: =IF(NOT(N4="NA"),1,"NA") -> NA | T4: =IF(NOT(O4="NA"),1,"NA") -> 1 | U4: =SUM(Q4:T4) -> 3 | V4: X | Z4: =SUM(Z6:Z11) -> 93
A5: 288 | B5: 45185 | C5: Lake Chauncy | D5: Chauncy | E5: Aphanizomenon (10%), Dolichospermum (60%), Microcystis (15%), Microcystis Debris (15%), Woronichinia (0%) | F5: 45185 | G5: Lake Chauncy | H5: Chauncy | I5: Aphanizomenon (10%), Dolichospermum (60%), Microcystis (15%), Microcystis Debris (15%), Woronichinia (0%) | J5: 10 | K5: 60 | L5: 15 | M5: 15 | N5: NA | O5: 0 | P5: =COUNTA(J5:O5)-COUNTIF(J5:O5,"NA") -> 5 | Q5: =IF(NOT(J5="NA"),1,"NA") -> 1 | R5: =IF(NOT(L5="NA"),1,"NA") -> 1 | S5: =IF(NOT(N5="NA"),1,"NA") -> NA | T5: =IF(NOT(O5="NA"),1,"NA") -> 1 | U5: =SUM(Q5:T5) -> 3 | V5: X | X5: sum.check | Y5: all | Z5: target.genera
A6: 208 | B6: 45145 | C6: Singletary Lake | D6: Singletary | E6: Aphanizomenon (25%), Oscillatoria (50%), Woronichinia (25%) | F6: 45145 | G6: Singletary Lake | H6: Singletary | I6: Aphanizomenon (25%), Oscillatoria (50%), Woronichinia (25%) | J6: 25 | K6: NA | L6: NA | M6: NA | N6: 50 | O6: 25 | P6: =COUNTA(J6:O6)-COUNTIF(J6:O6,"NA") -> 3 | Q6: =IF(NOT(J6="NA"),1,"NA") -> 1 | R6: =IF(NOT(L6="NA"),1,"NA") -> NA | S6: =IF(NOT(N6="NA"),1,"NA") -> 1 | T6: =IF(NOT(O6="NA"),1,"NA") -> 1 | U6: =SUM(Q6:T6) -> 3 | X6: 1 | Y6: =COUNTIF(P$4:P$392,$X6) -> 71 | Z6: =COUNTIF(U$4:U$392,X6) -> 66
A7: 166 | B7: 45129 | C7: Jordan Pond | D7: Jordan | E7: Aphanizomenon (50%), Dolichospermum (25%), Microcystis (25%) | F7: 45129 | G7: Jordan Pond | H7: Jordan | I7: Aphanizomenon (50%), Dolichospermum (25%), Microcystis (25%) | J7: 50 | K7: 25 | L7: 25 | M7: NA | N7: NA | O7: NA | P7: =COUNTA(J7:O7)-COUNTIF(J7:O7,"NA") -> 3 | Q7: =IF(NOT(J7="NA"),1,"NA") -> 1 | R7: =IF(NOT(L7="NA"),1,"NA") -> 1 | S7: =IF(NOT(N7="NA"),1,"NA") -> NA | T7: =IF(NOT(O7="NA"),1,"NA") -> NA | U7: =SUM(Q7:T7) -> 2 | X7: 2 | Y7: =COUNTIF(P$4:P$392,$X7) -> 46 | Z7: =COUNTIF(U$4:U$392,X7) -> 24
A8: 182 | B8: 45145 | C8: Burncoat Pond | D8: Burncoat | E8: Aphanizomenon (50%), Dolichospermum (25%), Microcystis (25%) | F8: 45145 | G8: Burncoat Pond | H8: Burncoat | I8: Aphanizomenon (50%), Dolichospermum (25%), Microcystis (25%) | J8: 50 | K8: 25 | L8: 25 | M8: NA | N8: NA | O8: NA | P8: =COUNTA(J8:O8)-COUNTIF(J8:O8,"NA") -> 3 | Q8: =IF(NOT(J8="NA"),1,"NA") -> 1 | R8: =IF(NOT(L8="NA"),1,"NA") -> 1 | S8: =IF(NOT(N8="NA"),1,"NA") -> NA | T8: =IF(NOT(O8="NA"),1,"NA") -> NA | U8: =SUM(Q8:T8) -> 2 | X8: 3 | Y8: =COUNTIF(P$4:P$392,$X8) -> 27 | Z8: =COUNTIF(U$4:U$392,X8) -> 3
A9: 196 | B9: 45145 | C9: Jordan Pond | D9: Jordan | E9: Aphanizomenon (25%), Dolichospermum (25%), Microcystis (50%) | F9: 45145 | G9: Jordan Pond | H9: Jordan | I9: Aphanizomenon (25%), Dolichospermum (25%), Microcystis (50%) | J9: 25 | K9: 25 | L9: 50 | M9: NA | N9: NA | O9: NA | P9: =COUNTA(J9:O9)-COUNTIF(J9:O9,"NA") -> 3 | Q9: =IF(NOT(J9="NA"),1,"NA") -> 1 | R9: =IF(NOT(L9="NA"),1,"NA") -> 1 | S9: =IF(NOT(N9="NA"),1,"NA") -> NA | T9: =IF(NOT(O9="NA"),1,"NA") -> NA | U9: =SUM(Q9:T9) -> 2 | X9: 4 | Y9: =COUNTIF(P$4:P$392,$X9) -> 7 | Z9: =COUNTIF(U$4:U$392,X9) -> 0
A10: 212 | B10: 45157 | C10: Burncoat Pond | D10: Burncoat | E10: Aphanizomenon (85%), Dolichospermum (5%), Microcystis (5%) | F10: 45157 | G10: Burncoat Pond | H10: Burncoat | I10: Aphanizomenon (85%), Dolichospermum (5%), Microcystis (5%) | J10: 85 | K10: 5 | L10: 5 | M10: NA | N10: NA | O10: NA | P10: =COUNTA(J10:O10)-COUNTIF(J10:O10,"NA") -> 3 | Q10: =IF(NOT(J10="NA"),1,"NA") -> 1 | R10: =IF(NOT(L10="NA"),1,"NA") -> 1 | S10: =IF(NOT(N10="NA"),1,"NA") -> NA | T10: =IF(NOT(O10="NA"),1,"NA") -> NA | U10: =SUM(Q10:T10) -> 2 | X10: 5 | Y10: =COUNTIF(P$4:P$392,$X10) -> 2 | Z10: =COUNTIF(U$4:U$392,X10) -> 0
A11: 242 | B11: 45174 | C11: Burncoat Pond | D11: Burncoat | E11: Aphanizomenon (75%), Microcystis (20%), Microcystis Debris (5%) | F11: 45174 | G11: Burncoat Pond | H11: Burncoat | I11: Aphanizomenon (75%), Microcystis (20%), Microcystis Debris (5%) | J11: 75 | K11: NA | L11: 20 | M11: 5 | N11: NA | O11: NA | P11: =COUNTA(J11:O11)-COUNTIF(J11:O11,"NA") -> 3 | Q11: =IF(NOT(J11="NA"),1,"NA") -> 1 | R11: =IF(NOT(L11="NA"),1,"NA") -> 1 | S11: =IF(NOT(N11="NA"),1,"NA") -> NA | T11: =IF(NOT(O11="NA"),1,"NA") -> NA | U11: =SUM(Q11:T11) -> 2 | X11: 6 | Y11: =COUNTIF(P$4:P$392,$X11) -> 0 | Z11: =COUNTIF(U$4:U$392,X11) -> 0
A12: 292 | B12: 45185 | C12: Little Indian Lake | D12: L.Indian | E12: Aphanizomenon (20%), Dolichospermum (75%), Microcystis (5%) | F12: 45185 | G12: Little Indian Lake | H12: L.Indian | I12: Aphanizomenon (20%), Dolichospermum (75%), Microcystis (5%) | J12: 20 | K12: 75 | L12: 5 | M12: NA | N12: NA | O12: NA | P12: =COUNTA(J12:O12)-COUNTIF(J12:O12,"NA") -> 3 | Q12: =IF(NOT(J12="NA"),1,"NA") -> 1 | R12: =IF(NOT(L12="NA"),1,"NA") -> 1 | S12: =IF(NOT(N12="NA"),1,"NA") -> NA | T12: =IF(NOT(O12="NA"),1,"NA") -> NA | U12: =SUM(Q12:T12) -> 2
A13: 318 | B13: 45201 | C13: Lake Chauncy | D13: Chauncy | E13: Aphanizomenon (75%), Dolichospermum (24%), Microcystis (1%) | F13: 45201 | G13: Lake Chauncy | H13: Chauncy | I13: Aphanizomenon (75%), Dolichospermum (24%), Microcystis (1%) | J13: 75 | K13: 24 | L13: 1 | M13: NA | N13: NA | O13: NA | P13: =COUNTA(J13:O13)-COUNTIF(J13:O13,"NA") -> 3 | Q13: =IF(NOT(J13="NA"),1,"NA") -> 1 | R13: =IF(NOT(L13="NA"),1,"NA") -> 1 | S13: =IF(NOT(N13="NA"),1,"NA") -> NA | T13: =IF(NOT(O13="NA"),1,"NA") -> NA | U13: =SUM(Q13:T13) -> 2
A14: 332 | B14: 45213 | C14: Burncoat Pond | D14: Burncoat | E14: Aphanizomenon (40%), Microcystis (50%), Microcystis Debris (10%) | F14: 45213 | G14: Burncoat Pond | H14: Burncoat | I14: Aphanizomenon (40%), Microcystis (50%), Microcystis Debris (10%) | J14: 40 | K14: NA | L14: 50 | M14: 10 | N14: NA | O14: NA | P14: =COUNTA(J14:O14)-COUNTIF(J14:O14,"NA") -> 3 | Q14: =IF(NOT(J14="NA"),1,"NA") -> 1 | R14: =IF(NOT(L14="NA"),1,"NA") -> 1 | S14: =IF(NOT(N14="NA"),1,"NA") -> NA | T14: =IF(NOT(O14="NA"),1,"NA") -> NA | U14: =SUM(Q14:T14) -> 2
A15: 135 | B15: 45117 | C15: Indian Lake | D15: Indian | E15: Aphanizomenon (25%), Dolichospermum (25%), Woronichinia (50%) | F15: 45117 | G15: Indian Lake | H15: Indian | I15: Aphanizomenon (25%), Dolichospermum (25%), Woronichinia (50%) | J15: 25 | K15: 25 | L15: NA | M15: NA | N15: NA | O15: 50 | P15: =COUNTA(J15:O15)-COUNTIF(J15:O15,"NA") -> 3 | Q15: =IF(NOT(J15="NA"),1,"NA") -> 1 | R15: =IF(NOT(L15="NA"),1,"NA") -> NA | S15: =IF(NOT(N15="NA"),1,"NA") -> NA | T15: =IF(NOT(O15="NA"),1,"NA") -> 1 | U15: =SUM(Q15:T15) -> 2 | V15: X
A16: 168 | B16: 45129 | C16: Lake Chauncy | D16: Chauncy | E16: Aphanizomenon (25%), Dolichospermum (50%), Microcystis Debris (20%), Woronichinia (5%) | F16: 45129 | G16: Lake Chauncy | H16: Chauncy | I16: Aphanizomenon (25%), Dolichospermum (50%), Microcystis Debris (20%), Woronichinia (5%) | J16: 25 | K16: 50 | L16: NA | M16: 20 | N16: NA | O16: 5 | P16: =COUNTA(J16:O16)-COUNTIF(J16:O16,"NA") -> 4 | Q16: =IF(NOT(J16="NA"),1,"NA") -> 1 | R16: =IF(NOT(L16="NA"),1,"NA") -> NA | S16: =IF(NOT(N16="NA"),1,"NA") -> NA | T16: =IF(NOT(O16="NA"),1,"NA") -> 1 | U16: =SUM(Q16:T16) -> 2 | V16: X
A17: 194 | B17: 45145 | C17: Green Hill Park Pond | D17: Green.Hill | E17: Aphanizomenon (25%), Dolichospermum (50%), Microcystis Debris (5%), Woronichinia (20%) | F17: 45145 | G17: Green Hill Park Pond | H17: Green.Hill | I17: Aphanizomenon (25%), Dolichospermum (50%), Microcystis Debris (5%), Woronichinia (20%) | J17: 25 | K17: 50 | L17: NA | M17: 5 | N17: NA | O17: 20 | P17: =COUNTA(J17:O17)-COUNTIF(J17:O17,"NA") -> 4 | Q17: =IF(NOT(J17="NA"),1,"NA") -> 1 | R17: =IF(NOT(L17="NA"),1,"NA") -> NA | S17: =IF(NOT(N17="NA"),1,"NA") -> NA | T17: =IF(NOT(O17="NA"),1,"NA") -> 1 | U17: =SUM(Q17:T17) -> 2 | V17: X
A18: 200 | B18: 45145 | C18: Lake Quinsigamond | D18: Quinsigamond | E18: Aphanizomenon (40%), Dolichospermum (40%), Microcystis Debris (10%), Woronichinia (10%) | F18: 45145 | G18: Lake Quinsigamond | H18: Quinsigamond | I18: Aphanizomenon (40%), Dolichospermum (40%), Microcystis Debris (10%), Woronichinia (10%) | J18: 40 | K18: 40 | L18: NA | M18: 10 | N18: NA | O18: 10 | P18: =COUNTA(J18:O18)-COUNTIF(J18:O18,"NA") -> 4 | Q18: =IF(NOT(J18="NA"),1,"NA") -> 1 | R18: =IF(NOT(L18="NA"),1,"NA") -> NA | S18: =IF(NOT(N18="NA"),1,"NA") -> NA | T18: =IF(NOT(O18="NA"),1,"NA") -> 1 | U18: =SUM(Q18:T18) -> 2 | V18: X | Z18: Lake.date | AA18: date.text | AB18: Date | AC18: Waterbody | AD18: Waterbody.edit | AE18: Dominance | AF18: Aphanizomenon | AG18: Dolichospermum | AH18: Microcystis | AI18: Microcystis_Debris | AJ18: Oscillatoria | AK18: Woronichinia | AL18: NA.count | AM18: Aph.check | AN18: Micro.check | AO18: Osc.check | AP18: Wor.check | AQ18: sum.checks | AR18: select.set
A19: 228 | B19: 45157 | C19: Lake Chauncy | D19: Chauncy | E19: Aphanizomenon (50%), Dolichospermum (25%), Woronichinia (0%) | F19: 45157 | G19: Lake Chauncy | H19: Chauncy | I19: Aphanizomenon (50%), Dolichospermum (25%), Woronichinia (0%) | J19: 50 | K19: 25 | L19: NA | M19: NA | N19: NA | O19: 0 | P19: =COUNTA(J19:O19)-COUNTIF(J19:O19,"NA") -> 3 | Q19: =IF(NOT(J19="NA"),1,"NA") -> 1 | R19: =IF(NOT(L19="NA"),1,"NA") -> NA | S19: =IF(NOT(N19="NA"),1,"NA") -> NA | T19: =IF(NOT(O19="NA"),1,"NA") -> 1 | U19: =SUM(Q19:T19) -> 2 | Z19: =CONCATENATE(AD19,"#",AA19) -> Chauncy#2023-08-07 | AA19: 2023-08-07 | AB19: 45145 | AC19: Lake Chauncy | AD19: Chauncy | AE19: Aphanizomenon (10%), Dolichospermum (60%), Microcystis (10%), Microcystis Debris (20%), Woronichinia (0%) | AF19: 10 | AG19: 60 | AH19: 10 | AI19: 20 | AJ19: NA | AK19: 0 | AL19: 5 | AM19: 1 | AN19: 1 | AO19: NA | AP19: 1 | AQ19: 3 | AR19: X | AS19: =VLOOKUP(Z19,'folder names img count cmds'!I$4:I$651,2,FALSE) -> #REF!
A20: 230 | B20: 45157 | C20: Lake Quinsigamond | D20: Quinsigamond | E20: Aphanizomenon (75%), Dolichospermum (5%), Microcystis Debris (20%), Woronichinia (0%) | F20: 45157 | G20: Lake Quinsigamond | H20: Quinsigamond | I20: Aphanizomenon (75%), Dolichospermum (5%), Microcystis Debris (20%), Woronichinia (0%) | J20: 75 | K20: 5 | L20: NA | M20: 20 | N20: NA | O20: 0 | P20: =COUNTA(J20:O20)-COUNTIF(J20:O20,"NA") -> 4 | Q20: =IF(NOT(J20="NA"),1,"NA") -> 1 | R20: =IF(NOT(L20="NA"),1,"NA") -> NA | S20: =IF(NOT(N20="NA"),1,"NA") -> NA | T20: =IF(NOT(O20="NA"),1,"NA") -> 1 | U20: =SUM(Q20:T20) -> 2 | V20: X | Z20: =CONCATENATE(AD20,"#",AA20) -> Chauncy#2023-09-16 | AA20: 2023-09-16 | AB20: 45185 | AC20: Lake Chauncy | AD20: Chauncy | AE20: Aphanizomenon (10%), Dolichospermum (60%), Microcystis (15%), Microcystis Debris (15%), Woronichinia (0%) | AF20: 10 | AG20: 60 | AH20: 15 | AI20: 15 | AJ20: NA | AK20: 0 | AL20: 5 | AM20: 1 | AN20: 1 | AO20: NA | AP20: 1 | AQ20: 3 | AR20: X | AS20: =VLOOKUP(Z20,'folder names img count cmds'!I$4:I$651,2,FALSE) -> #REF!
A21: 244 | B21: 45174 | C21: Coes Reservoir | D21: Coes.R | E21: Aphanizomenon (45%), Dolichospermum (50%), Woronichinia (5%) | F21: 45174 | G21: Coes Reservoir | H21: Coes.R | I21: Aphanizomenon (45%), Dolichospermum (50%), Woronichinia (5%) | J21: 45 | K21: 50 | L21: NA | M21: NA | N21: NA | O21: 5 | P21: =COUNTA(J21:O21)-COUNTIF(J21:O21,"NA") -> 3 | Q21: =IF(NOT(J21="NA"),1,"NA") -> 1 | R21: =IF(NOT(L21="NA"),1,"NA") -> NA | S21: =IF(NOT(N21="NA"),1,"NA") -> NA | T21: =IF(NOT(O21="NA"),1,"NA") -> 1 | U21: =SUM(Q21:T21) -> 2 | Z21: =CONCATENATE(AD21,"#",AA21) -> Indian#2023-07-10 | AA21: 2023-07-10 | AB21: 45117 | AC21: Indian Lake | AD21: Indian | AE21: Aphanizomenon (25%), Dolichospermum (25%), Woronichinia (50%) | AF21: 25 | AG21: 25 | AH21: NA | AI21: NA | AJ21: NA | AK21: 50 | AL21: 3 | AM21: 1 | AN21: NA | AO21: NA | AP21: 1 | AQ21: 2 | AR21: X | AS21: =VLOOKUP(Z21,'folder names img count cmds'!I$4:I$651,2,FALSE) -> #REF!
A22: 260 | B22: 45174 | C22: Lake Quinsigamond | D22: Quinsigamond | E22: Aphanizomenon (75%), Dolichospermum (5%), Microcystis Debris (15%), Woronichinia (5%) | F22: 45174 | G22: Lake Quinsigamond | H22: Quinsigamond | I22: Aphanizomenon (75%), Dolichospermum (5%), Microcystis Debris (15%), Woronichinia (5%) | J22: 75 | K22: 5 | L22: NA | M22: 15 | N22: NA | O22: 5 | P22: =COUNTA(J22:O22)-COUNTIF(J22:O22,"NA") -> 4 | Q22: =IF(NOT(J22="NA"),1,"NA") -> 1 | R22: =IF(NOT(L22="NA"),1,"NA") -> NA | S22: =IF(NOT(N22="NA"),1,"NA") -> NA | T22: =IF(NOT(O22="NA"),1,"NA") -> 1 | U22: =SUM(Q22:T22) -> 2 | V22: X | Z22: =CONCATENATE(AD22,"#",AA22) -> Chauncy#2023-07-22 | AA22: 2023-07-22 | AB22: 45129 | AC22: Lake Chauncy | AD22: Chauncy | AE22: Aphanizomenon (25%), Dolichospermum (50%), Microcystis Debris (20%), Woronichinia (5%) | AF22: 25 | AG22: 50 | AH22: NA | AI22: 20 | AJ22: NA | AK22: 5 | AL22: 4 | AM22: 1 | AN22: NA | AO22: NA | AP22: 1 | AQ22: 2 | AR22: X | AS22: =VLOOKUP(Z22,'folder names img count cmds'!I$4:I$651,2,FALSE) -> #REF!
A23: 350 | B23: 45213 | C23: Lake Quinsigamond | D23: Quinsigamond | E23: Aphanizomenon (75%), Woronichinia (25%) | F23: 45213 | G23: Lake Quinsigamond | H23: Quinsigamond | I23: Aphanizomenon (75%), Woronichinia (25%) | J23: 75 | K23: NA | L23: NA | M23: NA | N23: NA | O23: 25 | P23: =COUNTA(J23:O23)-COUNTIF(J23:O23,"NA") -> 2 | Q23: =IF(NOT(J23="NA"),1,"NA") -> 1 | R23: =IF(NOT(L23="NA"),1,"NA") -> NA | S23: =IF(NOT(N23="NA"),1,"NA") -> NA | T23: =IF(NOT(O23="NA"),1,"NA") -> 1 | U23: =SUM(Q23:T23) -> 2 | Z23: =CONCATENATE(AD23,"#",AA23) -> Green.Hill#2023-08-07 | AA23: 2023-08-07 | AB23: 45145 | AC23: Green Hill Park Pond | AD23: Green.Hill | AE23: Aphanizomenon (25%), Dolichospermum (50%), Microcystis Debris (5%), Woronichinia (20%) | AF23: 25 | AG23: 50 | AH23: NA | AI23: 5 | AJ23: NA | AK23: 20 | AL23: 4 | AM23: 1 | AN23: NA | AO23: NA | AP23: 1 | AQ23: 2 | AR23: X | AS23: =VLOOKUP(Z23,'folder names img count cmds'!I$4:I$651,2,FALSE) -> #REF!
A24: 286 | B24: 45185 | C24: Jordan Pond | D24: Jordan | E24: Microcystis (75%), Microcystis Debris (5%), Oscillatoria (20%) | F24: 45185 | G24: Jordan Pond | H24: Jordan | I24: Microcystis (75%), Microcystis Debris (5%), Oscillatoria (20%) | J24: NA | K24: NA | L24: 75 | M24: 5 | N24: 20 | O24: NA | P24: =COUNTA(J24:O24)-COUNTIF(J24:O24,"NA") -> 3 | Q24: =IF(NOT(J24="NA"),1,"NA") -> NA | R24: =IF(NOT(L24="NA"),1,"NA") -> 1 | S24: =IF(NOT(N24="NA"),1,"NA") -> 1 | T24: =IF(NOT(O24="NA"),1,"NA") -> NA | U24: =SUM(Q24:T24) -> 2 | V24: X | Z24: =CONCATENATE(AD24,"#",AA24) -> Quinsigamond#2023-08-07 | AA24: 2023-08-07 | AB24: 45145 | AC24: Lake Quinsigamond | AD24: Quinsigamond | AE24: Aphanizomenon (40%), Dolichospermum (40%), Microcystis Debris (10%), Woronichinia (10%) | AF24: 40 | AG24: 40 | AH24: NA | AI24: 10 | AJ24: NA | AK24: 10 | AL24: 4 | AM24: 1 | AN24: NA | AO24: NA | AP24: 1 | AQ24: 2 | AR24: X | AS24: =VLOOKUP(Z24,'folder names img count cmds'!I$4:I$651,2,FALSE) -> #REF!
A25: 225 | B25: 45157 | C25: Indian Lake | D25: Indian | E25: Dolichospermum (15%), Microcystis (15%), Microcystis Debris (70%), Woronichinia (0%) | F25: 45157 | G25: Indian Lake | H25: Indian | I25: Dolichospermum (15%), Microcystis (15%), Microcystis Debris (70%), Woronichinia (0%) | J25: NA | K25: 15 | L25: 15 | M25: 70 | N25: NA | O25: 0 | P25: =COUNTA(J25:O25)-COUNTIF(J25:O25,"NA") -> 4 | Q25: =IF(NOT(J25="NA"),1,"NA") -> NA | R25: =IF(NOT(L25="NA"),1,"NA") -> 1 | S25: =IF(NOT(N25="NA"),1,"NA") -> NA | T25: =IF(NOT(O25="NA"),1,"NA") -> 1 | U25: =SUM(Q25:T25) -> 2 | V25: X | Z25: =CONCATENATE(AD25,"#",AA25) -> Quinsigamond#2023-08-19 | AA25: 2023-08-19 | AB25: 45157 | AC25: Lake Quinsigamond | AD25: Quinsigamond | AE25: Aphanizomenon (75%), Dolichospermum (5%), Microcystis Debris (20%), Woronichinia (0%) | AF25: 75 | AG25: 5 | AH25: NA | AI25: 20 | AJ25: NA | AK25: 0 | AL25: 4 | AM25: 1 | AN25: NA | AO25: NA | AP25: 1 | AQ25: 2 | AR25: X | AS25: =VLOOKUP(Z25,'folder names img count cmds'!I$4:I$651,2,FALSE) -> #REF!
A26: 285 | B26: 45185 | C26: Indian Lake | D26: Indian | E26: Microcystis (10%), Microcystis Debris (85%), Woronichinia (5%) | F26: 45185 | G26: Indian Lake | H26: Indian | I26: Microcystis (10%), Microcystis Debris (85%), Woronichinia (5%) | J26: NA | K26: NA | L26: 10 | M26: 85 | N26: NA | O26: 5 | P26: =COUNTA(J26:O26)-COUNTIF(J26:O26,"NA") -> 3 | Q26: =IF(NOT(J26="NA"),1,"NA") -> NA | R26: =IF(NOT(L26="NA"),1,"NA") -> 1 | S26: =IF(NOT(N26="NA"),1,"NA") -> NA | T26: =IF(NOT(O26="NA"),1,"NA") -> 1 | U26: =SUM(Q26:T26) -> 2 | Z26: =CONCATENATE(AD26,"#",AA26) -> Quinsigamond#2023-09-05 | AA26: 2023-09-05 | AB26: 45174 | AC26: Lake Quinsigamond | AD26: Quinsigamond | AE26: Aphanizomenon (75%), Dolichospermum (5%), Microcystis Debris (15%), Woronichinia (5%) | AF26: 75 | AG26: 5 | AH26: NA | AI26: 15 | AJ26: NA | AK26: 5 | AL26: 4 | AM26: 1 | AN26: NA | AO26: NA | AP26: 1 | AQ26: 2 | AR26: X | AS26: =VLOOKUP(Z26,'folder names img count cmds'!I$4:I$651,2,FALSE) -> #REF!
A27: 344 | B27: 45213 | C27: Green Hill Park Pond | D27: Green.Hill | E27: Dolichospermum (40%), Microcystis (10%), Woronichinia (50%) | F27: 45213 | G27: Green Hill Park Pond | H27: Green.Hill | I27: Dolichospermum (40%), Microcystis (10%), Woronichinia (50%) | J27: NA | K27: 40 | L27: 10 | M27: NA | N27: NA | O27: 50 | P27: =COUNTA(J27:O27)-COUNTIF(J27:O27,"NA") -> 3 | Q27: =IF(NOT(J27="NA"),1,"NA") -> NA | R27: =IF(NOT(L27="NA"),1,"NA") -> 1 | S27: =IF(NOT(N27="NA"),1,"NA") -> NA | T27: =IF(NOT(O27="NA"),1,"NA") -> 1 | U27: =SUM(Q27:T27) -> 2 | V27: X | Z27: =CONCATENATE(AD27,"#",AA27) -> Jordan#2023-09-16 | AA27: 2023-09-16 | AB27: 45185 | AC27: Jordan Pond | AD27: Jordan | AE27: Microcystis (75%), Microcystis Debris (5%), Oscillatoria (20%) | AF27: NA | AG27: NA | AH27: 75 | AI27: 5 | AJ27: 20 | AK27: NA | AL27: 3 | AM27: NA | AN27: 1 | AO27: 1 | AP27: NA | AQ27: 2 | AR27: X | AS27: =VLOOKUP(Z27,'folder names img count cmds'!I$4:I$651,2,FALSE) -> #N/A
A28: 345 | B28: 45213 | C28: Indian Lake | D28: Indian | E28: Dolichospermum (20%), Microcystis (5%), Microcystis Debris (50%), Woronichinia (25%) | F28: 45213 | G28: Indian Lake | H28: Indian | I28: Dolichospermum (20%), Microcystis (5%), Microcystis Debris (50%), Woronichinia (25%) | J28: NA | K28: 20 | L28: 5 | M28: 50 | N28: NA | O28: 25 | P28: =COUNTA(J28:O28)-COUNTIF(J28:O28,"NA") -> 4 | Q28: =IF(NOT(J28="NA"),1,"NA") -> NA | R28: =IF(NOT(L28="NA"),1,"NA") -> 1 | S28: =IF(NOT(N28="NA"),1,"NA") -> NA | T28: =IF(NOT(O28="NA"),1,"NA") -> 1 | U28: =SUM(Q28:T28) -> 2 | V28: X | Z28: =CONCATENATE(AD28,"#",AA28) -> Indian#2023-08-19 | AA28: 2023-08-19 | AB28: 45157 | AC28: Indian Lake | AD28: Indian | AE28: Dolichospermum (15%), Microcystis (15%), Microcystis Debris (70%), Woronichinia (0%) | AF28: NA | AG28: 15 | AH28: 15 | AI28: 70 | AJ28: NA | AK28: 0 | AL28: 4 | AM28: NA | AN28: 1 | AO28: NA | AP28: 1 | AQ28: 2 | AR28: X | AS28: =VLOOKUP(Z28,'folder names img count cmds'!I$4:I$651,2,FALSE) -> #REF!
A29: 373 | B29: 45229 | C29: Green Hill Park Pond | D29: Green.Hill | E29: Dolichospermum (75%), Microcystis (15%), Woronichinia (10%) | F29: 45229 | G29: Green Hill Park Pond | H29: Green.Hill | I29: Dolichospermum (75%), Microcystis (15%), Woronichinia (10%) | J29: NA | K29: 75 | L29: 15 | M29: NA | N29: NA | O29: 10 | P29: =COUNTA(J29:O29)-COUNTIF(J29:O29,"NA") -> 3 | Q29: =IF(NOT(J29="NA"),1,"NA") -> NA | R29: =IF(NOT(L29="NA"),1,"NA") -> 1 | S29: =IF(NOT(N29="NA"),1,"NA") -> NA | T29: =IF(NOT(O29="NA"),1,"NA") -> 1 | U29: =SUM(Q29:T29) -> 2 | Z29: =CONCATENATE(AD29,"#",AA29) -> Green.Hill#2023-10-14 | AA29: 2023-10-14 | AB29: 45213 | AC29: Green Hill Park Pond | AD29: Green.Hill | AE29: Dolichospermum (40%), Microcystis (10%), Woronichinia (50%) | AF29: NA | AG29: 40 | AH29: 10 | AI29: NA | AJ29: NA | AK29: 50 | AL29: 3 | AM29: NA | AN29: 1 | AO29: NA | AP29: 1 | AQ29: 2 | AR29: X | AS29: =VLOOKUP(Z29,'folder names img count cmds'!I$4:I$651,2,FALSE) -> #REF!
A30: 296 | B30: 45185 | C30: Patch Reservoir | D30: Patch.R | E30: Dolichospermum (75%), Oscillatoria (20%), Woronichinia (5%) | F30: 45185 | G30: Patch Reservoir | H30: Patch.R | I30: Dolichospermum (75%), Oscillatoria (20%), Woronichinia (5%) | J30: NA | K30: 75 | L30: NA | M30: NA | N30: 20 | O30: 5 | P30: =COUNTA(J30:O30)-COUNTIF(J30:O30,"NA") -> 3 | Q30: =IF(NOT(J30="NA"),1,"NA") -> NA | R30: =IF(NOT(L30="NA"),1,"NA") -> NA | S30: =IF(NOT(N30="NA"),1,"NA") -> 1 | T30: =IF(NOT(O30="NA"),1,"NA") -> 1 | U30: =SUM(Q30:T30) -> 2 | V30: X | Z30: =CONCATENATE(AD30,"#",AA30) -> Indian#2023-10-14 | AA30: 2023-10-14 | AB30: 45213 | AC30: Indian Lake | AD30: Indian | AE30: Dolichospermum (20%), Microcystis (5%), Microcystis Debris (50%), Woronichinia (25%) | AF30: NA | AG30: 20 | AH30: 5 | AI30: 50 | AJ30: NA | AK30: 25 | AL30: 4 | AM30: NA | AN30: 1 | AO30: NA | AP30: 1 | AQ30: 2 | AR30: X | AS30: =VLOOKUP(Z30,'folder names img count cmds'!I$4:I$651,2,FALSE) -> #REF!
A31: 18 | B31: 45045 | C31: Lake Chauncy | D31: Chauncy | E31: Aphanizomenon (100%) | F31: 45045 | G31: Lake Chauncy | H31: Chauncy | I31: Aphanizomenon (100%) | J31: 100 | K31: NA | L31: NA | M31: NA | N31: NA | O31: NA | P31: =COUNTA(J31:O31)-COUNTIF(J31:O31,"NA") -> 1 | Q31: =IF(NOT(J31="NA"),1,"NA") -> 1 | R31: =IF(NOT(L31="NA"),1,"NA") -> NA | S31: =IF(NOT(N31="NA"),1,"NA") -> NA | T31: =IF(NOT(O31="NA"),1,"NA") -> NA | U31: =SUM(Q31:T31) -> 1 | Z31: =CONCATENATE(AD31,"#",AA31) -> Patch.R#2023-09-16 | AA31: 2023-09-16 | AB31: 45185 | AC31: Patch Reservoir | AD31: Patch.R | AE31: Dolichospermum (75%), Oscillatoria (20%), Woronichinia (5%) | AF31: NA | AG31: 75 | AH31: NA | AI31: NA | AJ31: 20 | AK31: 5 | AL31: 3 | AM31: NA | AN31: NA | AO31: 1 | AP31: 1 | AQ31: 2 | AR31: X | AS31: =VLOOKUP(Z31,'folder names img count cmds'!I$4:I$651,2,FALSE) -> #REF!
A32: 62 | B32: 45073 | C32: Burncoat Pond | D32: Burncoat | E32: Aphanizomenon (50%), Dolichospermum (50%) | F32: 45073 | G32: Burncoat Pond | H32: Burncoat | I32: Aphanizomenon (50%), Dolichospermum (50%) | J32: 50 | K32: 50 | L32: NA | M32: NA | N32: NA | O32: NA | P32: =COUNTA(J32:O32)-COUNTIF(J32:O32,"NA") -> 2 | Q32: =IF(NOT(J32="NA"),1,"NA") -> 1 | R32: =IF(NOT(L32="NA"),1,"NA") -> NA | S32: =IF(NOT(N32="NA"),1,"NA") -> NA | T32: =IF(NOT(O32="NA"),1,"NA") -> NA | U32: =SUM(Q32:T32) -> 1 | Z32: =CONCATENATE(AD32,"#",AA32) -> Quinsigamond#2023-05-15 | AA32: 2023-05-15 | AB32: 45061 | AC32: Lake Quinsigamond | AD32: Quinsigamond | AE32: Microcystis (100%) | AF32: NA | AG32: NA | AH32: 100 | AI32: NA | AJ32: NA | AK32: NA | AL32: 1 | AM32: NA | AN32: 1 | AO32: NA | AP32: NA | AQ32: 1 | AR32: X | AS32: =VLOOKUP(Z32,'folder names img count cmds'!I$4:I$651,2,FALSE) -> #REF!
A33: 64 | B33: 45073 | C33: Coes Reservoir | D33: Coes.R | E33: Aphanizomenon (50%), Dolichospermum (50%) | F33: 45073 | G33: Coes Reservoir | H33: Coes.R | I33: Aphanizomenon (50%), Dolichospermum (50%) | J33: 50 | K33: 50 | L33: NA | M33: NA | N33: NA | O33: NA | P33: =COUNTA(J33:O33)-COUNTIF(J33:O33,"NA") -> 2 | Q33: =IF(NOT(J33="NA"),1,"NA") -> 1 | R33: =IF(NOT(L33="NA"),1,"NA") -> NA | S33: =IF(NOT(N33="NA"),1,"NA") -> NA | T33: =IF(NOT(O33="NA"),1,"NA") -> NA | U33: =SUM(Q33:T33) -> 1 | Z33: =CONCATENATE(AD33,"#",AA33) -> L.Indian#2023-05-15 | AA33: 2023-05-15 | AB33: 45061 | AC33: Little Indian Lake | AD33: L.Indian | AE33: Microcystis (100%) | AF33: NA | AG33: NA | AH33: 100 | AI33: NA | AJ33: NA | AK33: NA | AL33: 1 | AM33: NA | AN33: 1 | AO33: NA | AP33: NA | AQ33: 1 | AR33: X | AS33: =VLOOKUP(Z33,'folder names img count cmds'!I$4:I$651,2,FALSE) -> #REF!
A34: 94 | B34: 45089 | C34: Coes Reservoir | D34: Coes.R | E34: Aphanizomenon (25%), Dolichospermum (75%) | F34: 45089 | G34: Coes Reservoir | H34: Coes.R | I34: Aphanizomenon (25%), Dolichospermum (75%) | J34: 25 | K34: 75 | L34: NA | M34: NA | N34: NA | O34: NA | P34: =COUNTA(J34:O34)-COUNTIF(J34:O34,"NA") -> 2 | Q34: =IF(NOT(J34="NA"),1,"NA") -> 1 | R34: =IF(NOT(L34="NA"),1,"NA") -> NA | S34: =IF(NOT(N34="NA"),1,"NA") -> NA | T34: =IF(NOT(O34="NA"),1,"NA") -> NA | U34: =SUM(Q34:T34) -> 1 | Z34: =CONCATENATE(AD34,"#",AA34) -> Indian#2023-05-27 | AA34: 2023-05-27 | AB34: 45073 | AC34: Indian Lake | AD34: Indian | AE34: Microcystis (10%), Microcystis Debris (90%) | AF34: NA | AG34: NA | AH34: 10 | AI34: 90 | AJ34: NA | AK34: NA | AL34: 2 | AM34: NA | AN34: 1 | AO34: NA | AP34: NA | AQ34: 1 | AR34: X | AS34: =VLOOKUP(Z34,'folder names img count cmds'!I$4:I$651,2,FALSE) -> #REF!
A35: 104 | B35: 45089 | C35: Green Hill Park Pond | D35: Green.Hill | E35: Aphanizomenon (100%) | F35: 45089 | G35: Green Hill Park Pond | H35: Green.Hill | I35: Aphanizomenon (100%) | J35: 100 | K35: NA | L35: NA | M35: NA | N35: NA | O35: NA | P35: =COUNTA(J35:O35)-COUNTIF(J35:O35,"NA") -> 1 | Q35: =IF(NOT(J35="NA"),1,"NA") -> 1 | R35: =IF(NOT(L35="NA"),1,"NA") -> NA | S35: =IF(NOT(N35="NA"),1,"NA") -> NA | T35: =IF(NOT(O35="NA"),1,"NA") -> NA | U35: =SUM(Q35:T35) -> 1 | Z35: =CONCATENATE(AD35,"#",AA35) -> Salisbury#2023-05-27 | AA35: 2023-05-27 | AB35: 45073 | AC35: Salisbury Pond | AD35: Salisbury | AE35: Microcystis (25%), Microcystis Debris (75%) | AF35: NA | AG35: NA | AH35: 25 | AI35: 75 | AJ35: NA | AK35: NA | AL35: 2 | AM35: NA | AN35: 1 | AO35: NA | AP35: NA | AQ35: 1 | AR35: X | AS35: =VLOOKUP(Z35,'folder names img count cmds'!I$4:I$651,2,FALSE) -> #REF!
A36: 124 | B36: 45117 | C36: Coes Reservoir | D36: Coes.R | E36: Aphanizomenon (25%), Dolichospermum (75%) | F36: 45117 | G36: Coes Reservoir | H36: Coes.R | I36: Aphanizomenon (25%), Dolichospermum (75%) | J36: 25 | K36: 75 | L36: NA | M36: NA | N36: NA | O36: NA | P36: =COUNTA(J36:O36)-COUNTIF(J36:O36,"NA") -> 2 | Q36: =IF(NOT(J36="NA"),1,"NA") -> 1 | R36: =IF(NOT(L36="NA"),1,"NA") -> NA | S36: =IF(NOT(N36="NA"),1,"NA") -> NA | T36: =IF(NOT(O36="NA"),1,"NA") -> NA | U36: =SUM(Q36:T36) -> 1 | Z36: =CONCATENATE(AD36,"#",AA36) -> Indian#2023-06-12 | AA36: 2023-06-12 | AB36: 45089 | AC36: Indian Lake | AD36: Indian | AE36: Microcystis (20%), Microcystis Debris (80%) | AF36: NA | AG36: NA | AH36: 20 | AI36: 80 | AJ36: NA | AK36: NA | AL36: 2 | AM36: NA | AN36: 1 | AO36: NA | AP36: NA | AQ36: 1 | AR36: X | AS36: =VLOOKUP(Z36,'folder names img count cmds'!I$4:I$651,2,FALSE) -> #REF!
A37: 136 | B37: 45117 | C37: Jordan Pond | D37: Jordan | E37: Aphanizomenon (25%), Dolichospermum (75%) | F37: 45117 | G37: Jordan Pond | H37: Jordan | I37: Aphanizomenon (25%), Dolichospermum (75%) | J37: 25 | K37: 75 | L37: NA | M37: NA | N37: NA | O37: NA | P37: =COUNTA(J37:O37)-COUNTIF(J37:O37,"NA") -> 2 | Q37: =IF(NOT(J37="NA"),1,"NA") -> 1 | R37: =IF(NOT(L37="NA"),1,"NA") -> NA | S37: =IF(NOT(N37="NA"),1,"NA") -> NA | T37: =IF(NOT(O37="NA"),1,"NA") -> NA | U37: =SUM(Q37:T37) -> 1 | Z37: =CONCATENATE(AD37,"#",AA37) -> Lashaway#2023-07-10 | AA37: 2023-07-10 | AB37: 45117 | AC37: Lake Lashaway | AD37: Lashaway | AE37: Microcystis (100%) | AF37: NA | AG37: NA | AH37: 100 | AI37: NA | AJ37: NA | AK37: NA | AL37: 1 | AM37: NA | AN37: 1 | AO37: NA | AP37: NA | AQ37: 1 | AR37: X | AS37: =VLOOKUP(Z37,'folder names img count cmds'!I$4:I$651,2,FALSE) -> #REF!
A38: 140 | B38: 45117 | C38: Lake Quinsigamond | D38: Quinsigamond | E38: Aphanizomenon (75%), Dolichospermum (25%) | F38: 45117 | G38: Lake Quinsigamond | H38: Quinsigamond | I38: Aphanizomenon (75%), Dolichospermum (25%) | J38: 75 | K38: 25 | L38: NA | M38: NA | N38: NA | O38: NA | P38: =COUNTA(J38:O38)-COUNTIF(J38:O38,"NA") -> 2 | Q38: =IF(NOT(J38="NA"),1,"NA") -> 1 | R38: =IF(NOT(L38="NA"),1,"NA") -> NA | S38: =IF(NOT(N38="NA"),1,"NA") -> NA | T38: =IF(NOT(O38="NA"),1,"NA") -> NA | U38: =SUM(Q38:T38) -> 1 | Z38: =CONCATENATE(AD38,"#",AA38) -> Jordan#2023-09-05 | AA38: 2023-09-05 | AB38: 45174 | AC38: Jordan Pond | AD38: Jordan | AE38: Microcystis (25%), Microcystis Debris (75%) | AF38: NA | AG38: NA | AH38: 25 | AI38: 75 | AJ38: NA | AK38: NA | AL38: 2 | AM38: NA | AN38: 1 | AO38: NA | AP38: NA | AQ38: 1 | AR38: X | AS38: =VLOOKUP(Z38,'folder names img count cmds'!I$4:I$651,2,FALSE) -> #REF!
A39: 145 | B39: 45117 | C39: Patch Pond | D39: Patch.P | E39: Aphanizomenon (100%) | F39: 45117 | G39: Patch Pond | H39: Patch.P | I39: Aphanizomenon (100%) | J39: 100 | K39: NA | L39: NA | M39: NA | N39: NA | O39: NA | P39: =COUNTA(J39:O39)-COUNTIF(J39:O39,"NA") -> 1 | Q39: =IF(NOT(J39="NA"),1,"NA") -> 1 | R39: =IF(NOT(L39="NA"),1,"NA") -> NA | S39: =IF(NOT(N39="NA"),1,"NA") -> NA | T39: =IF(NOT(O39="NA"),1,"NA") -> NA | U39: =SUM(Q39:T39) -> 1 | Z39: =CONCATENATE(AD39,"#",AA39) -> Dark.Brook#2023-07-10 | AA39: 2023-07-10 | AB39: 45117 | AC39: Dark Brook Reservoir | AD39: Dark.Brook | AE39: Dolichospermum (50%), Oscillatoria (50%) | AF39: NA | AG39: 50 | AH39: NA | AI39: NA | AJ39: 50 | AK39: NA | AL39: 2 | AM39: NA | AN39: NA | AO39: 1 | AP39: NA | AQ39: 1 | AR39: X | AS39: =VLOOKUP(Z39,'folder names img count cmds'!I$4:I$651,2,FALSE) -> #N/A
A40: 146 | B40: 45117 | C40: Patch Reservoir | D40: Patch.R | E40: Aphanizomenon (25%), Dolichospermum (75%) | F40: 45117 | G40: Patch Reservoir | H40: Patch.R | I40: Aphanizomenon (25%), Dolichospermum (75%) | J40: 25 | K40: 75 | L40: NA | M40: NA | N40: NA | O40: NA | P40: =COUNTA(J40:O40)-COUNTIF(J40:O40,"NA") -> 2 | Q40: =IF(NOT(J40="NA"),1,"NA") -> 1 | R40: =IF(NOT(L40="NA"),1,"NA") -> NA | S40: =IF(NOT(N40="NA"),1,"NA") -> NA | T40: =IF(NOT(O40="NA"),1,"NA") -> NA | U40: =SUM(Q40:T40) -> 1 | Z40: =CONCATENATE(AD40,"#",AA40) -> Patch.P#2023-07-22 | AA40: 2023-07-22 | AB40: 45129 | AC40: Patch Pond | AD40: Patch.P | AE40: Oscillatoria (100%) | AF40: NA | AG40: NA | AH40: NA | AI40: NA | AJ40: 100 | AK40: NA | AL40: 1 | AM40: NA | AN40: NA | AO40: 1 | AP40: NA | AQ40: 1 | AR40: X | AS40: =VLOOKUP(Z40,'folder names img count cmds'!I$4:I$651,2,FALSE) -> #REF!
...

Sheet Pond name mapping
B2: Folder_name_replace#forspace | C2: Short.pond.name
B3: Bell#Pond | C3: Bell
B4: Bell | C4: Burncoat
B5: Burncoat#1 | C5: Burncoat
B6: Burncoat#Pond | C6: Burncoat
B7: Burncoat | C7: Burncoat
B8: Chauncy | C8: Chauncy
B9: Coes#Res | C9: Coes.R
B10: Coes#Reservoir | C10: Coes.R
B11: Coes | C11: Coes
B12: CoesPond | C12: Coes.R
B13: CoesRes | C13: Coes.R
... B91: Waushacum | C91: E.Waushacum

Sheet folder names img count cmds
A3: Folder | B3: Date | C3: Year | D3: Month | E3: Day | F3: Pond | G3: Pond.edit | H3: Date | I3: Pond.date | J3: edit folder name
A4: Bell Pond_5.15.2023_10X_TR1 no dilution-pp | B4: 45061 | C4: 2023 | D4: 5 | E4: 15 | F4: Bell#Pond | G4: =VLOOKUP(F4,'Pond name mapping'!B$3:C$91,2,FALSE) -> Bell | H4: 2023-05-15 | I4: =CONCATENATE(G4,"#",H4) -> Bell#2023-05-15 | J4: Bell\ Pond_5.15.2023_10X_TR1\ no\ dilution-pp
A5: Bell Pond_5.27.23_10x_AI1 no dilution-pp | B5: 45073 | C5: 2023 | D5: 5 | E5: 27 | F5: Bell#Pond | G5: =VLOOKUP(F5,'Pond name mapping'!B$3:C$91,2,FALSE) -> Bell | H5: 2023-05-27 | I5: =CONCATENATE(G5,"#",H5) -> Bell#2023-05-27 | J5: Bell\ Pond_5.27.23_10x_AI1\ no\ dilution-pp
A6: Bell Pond_6.12.2023_10x_TM no dilution-pp | B6: 45089 | C6: 2023 | D6: 6 | E6: 12 | F6: Bell#Pond | G6: =VLOOKUP(F6,'Pond name mapping'!B$3:C$91,2,FALSE) -> Bell | H6: 2023-06-12 | I6: =CONCATENATE(G6,"#",H6) -> Bell#2023-06-12 | J6: Bell\ Pond_6.12.2023_10x_TM\ no\ dilution-pp
A7: Bell Pond_6.24.2023_10x_TM no dilution-pp | B7: 45101 | C7: 2023 | D7: 6 | E7: 24 | F7: Bell#Pond | G7: =VLOOKUP(F7,'Pond name mapping'!B$3:C$91,2,FALSE) -> Bell | H7: 2023-06-24 | I7: =CONCATENATE(G7,"#",H7) -> Bell#2023-06-24 | J7: Bell\ Pond_6.24.2023_10x_TM\ no\ dilution-pp
A8: Bell Pond_7.10.2023_10x_TM 0.5 dilution-pp | B8: 45117 | C8: 2023 | D8: 7 | E8: 10 | F8: Bell#Pond | G8: =VLOOKUP(F8,'Pond name mapping'!B$3:C$91,2,FALSE) -> Bell | H8: 2023-07-10 | I8: =CONCATENATE(G8,"#",H8) -> Bell#2023-07-10 | J8: Bell\ Pond_7.10.2023_10x_TM\ 0.5\ dilution-pp
A9: Bell Pond_7.22.2023_10x_TM 0.5 dilution-PP | B9: 45129 | C9: 2023 | D9: 7 | E9: 22 | F9: Bell#Pond | G9: =VLOOKUP(F9,'Pond name mapping'!B$3:C$91,2,FALSE) -> Bell | H9: 2023-07-22 | I9: =CONCATENATE(G9,"#",H9) -> Bell#2023-07-22 | J9: Bell\ Pond_7.22.2023_10x_TM\ 0.5\ dilution-PP
A10: Bell Pond_8.7.2023_10x_TM 0.5 dilution-pp | B10: 45145 | C10: 2023 | D10: 8 | E10: 7 | F10: Bell#Pond | G10: =VLOOKUP(F10,'Pond name mapping'!B$3:C$91,2,FALSE) -> Bell | H10: 2023-08-07 | I10: =CONCATENATE(G10,"#",H10) -> Bell#2023-08-07 | J10: Bell\ Pond_8.7.2023_10x_TM\ 0.5\ dilution-pp
A11: Bell Pond_8.19.2023_10x_TM 0.5 dilution-PP | B11: 45157 | C11: 2023 | D11: 8 | E11: 19 | F11: Bell#Pond | G11: =VLOOKUP(F11,'Pond name mapping'!B$3:C$91,2,FALSE) -> Bell | H11: 2023-08-19 | I11: =CONCATENATE(G11,"#",H11) -> Bell#2023-08-19 | J11: Bell\ Pond_8.19.2023_10x_TM\ 0.5\ dilution-PP
A12: Bell Pond_9.16.2023_10x_TM 0.5 dilution-pp | B12: 45185 | C12: 2023 | D12: 9 | E12: 16 | F12: Bell#Pond | G12: =VLOOKUP(F12,'Pond name mapping'!B$3:C$91,2,FALSE) -> Bell | H12: 2023-09-16 | I12: =CONCATENATE(G12,"#",H12) -> Bell#2023-09-16 | J12: Bell\ Pond_9.16.2023_10x_TM\ 0.5\ dilution-pp
A13: Bell Pond_10.2.2023_10x_TM 0.5 dilution 1-pp | B13: 45201 | C13: 2023 | D13: 10 | E13: 2 | F13: Bell#Pond | G13: =VLOOKUP(F13,'Pond name mapping'!B$3:C$91,2,FALSE) -> Bell | H13: 2023-10-02 | I13: =CONCATENATE(G13,"#",H13) -> Bell#2023-10-02 | J13: Bell\ Pond_10.2.2023_10x_TM\ 0.5\ dilution\ 1-pp
A14: Bell Pond_10.14.2023_10x_TM 0.5 dilution -pp | B14: 45213 | C14: 2023 | D14: 10 | E14: 14 | F14: Bell#Pond | G14: =VLOOKUP(F14,'Pond name mapping'!B$3:C$91,2,FALSE) -> Bell | H14: 2023-10-14 | I14: =CONCATENATE(G14,"#",H14) -> Bell#2023-10-14 | J14: Bell\ Pond_10.14.2023_10x_TM\ 0.5\ dilution\ -pp
A15: Bell_4.29.23_10x_TR1 no dilution-pp | B15: 45045 | C15: 2023 | D15: 4 | E15: 29 | F15: Bell | G15: =VLOOKUP(F15,'Pond name mapping'!B$3:C$91,2,FALSE) -> Burncoat | H15: 2023-04-29 | I15: =CONCATENATE(G15,"#",H15) -> Burncoat#2023-04-29 | J15: Bell_4.29.23_10x_TR1\ no\ dilution-pp
... A651: Waushacum_CR9.24.22_10x_TR1-pp | B651: 44828 | C651: 2022 | D651: 9 | E651: 24 | F651: Waushacum | G651: =VLOOKUP(F651,'Pond name mapping'!B$3:C$91,2,FALSE) -> E.Waushacum | H651: 2022-09-24 | I651: =CONCATENATE(G651,"#",H651) -> E.Waushacum#2022-09-24 | J651: Waushacum_CR9.24.22_10x_TR1-pp

Sheet match 9.16 ...
C1: Match 9/16 samples?
C3: Bell Pond_9.16.2023_10x_TM 0.5 dilution-pp | D3: Bell Pond | E3: Bell | F3: none
D4: Burncoat Pond | E4: Burncoat | F4: NA
C5: Cooks Pond_9.16.2023_10x_TM 0.5 dilution-pp | D5: Coes Pond | E5: Coes.P | F5: NA
C6: Coes Reservoir_9.16.2023_10x_TM 0.5 dilution-pp | D6: Coes Reservoir | E6: Coes.R | F6: Aphanizomenon (25%), Dolichospermum (75%)
D7: Cooks Pond | E7: Crooks | F7: Microcystis Debris (100%)
C8: Crystal Pond_9.16.2023_10x_TM 0.5 dilution | D8: Crystal Pond | E8: Crystal | F8: none
C9: Crystal Pond_9.16.2023_10x_TM 0.5 dilution-pp
D10: Curtis Pond | E10: Curtis | F10: NA
D11: Dark Brook Reservoir | E11: Dark.Brook | F11: NA
C12: Waushacum_9.16.2023_10x_TM 0.5 dilution-pp | D12: East Lake Waushacum | E12: E.Waushacum | F12: none
C13: Ecotarium_9.16.2023_10x_TM 0.1 dilution-pp | D13: Ecotarium Pond | E13: Ecotarium | F13: none
C14: Elm Park_9.16.2023_10x_TM 0.1 dilution-pp | D14: Elm Park Pond | E14: Elm | F14: Dolichospermum (75%), Microcystis Debris (25%)
C15: Farm Pond_9.16.2023_10x_TM 0.5 dilution-pp | D15: Farm Pond | E15: Farm | F15: Dolichospermum (100%)
D16: Flint Pond | E16: Flint | F16: NA
C17: Green Hill Pond_9.16.2023_10x_TM 0.1 dilution | D17: Green Hill Park Pond | E17: Green.Hill | F17: Dolichospermum (95%), Woronichinia (5%)
C18: Green Hill Pond_9.16.2023_10x_TM 0.1 dilution-pp
C19: Indian Lake_9.16.2023_10x_TM 0.5 dilution-pp | D19: Indian Lake | E19: Indian | F19: Microcystis (10%), Microcystis Debris (85%), Woronichinia (5%)
C20: UNKNOWN_9.16.2023_10x_TM 0.5 dilution | D20: Jordan Pond | E20: Jordan | F20: Microcystis (75%), Microcystis Debris (5%), Oscillatoria (20%)
C21: Kiver Pond_9.16.2023_10x_TM 0.1 dilution-pp | D21: Kiver Pond | E21: Kiver | F21: NA
C22: Lake Chauncy_9.16.2023_10x_TM 0.5 dilution-pp | D22: Lake Chauncy | E22: Chauncy | F22: Aphanizomenon (10%), Dolichospermum (60%), Microcystis (15%), Microcystis Debris (15%), Woronichinia (0%)
C23: Lake Lashaway_9.16.2023_10x_TM 0.5 dilution-pp | D23: Lake Lashaway | E23: Lashaway | F23: Dolichospermum (50%), Woronichinia (50%)
C24: Lake Quinsigamond_9.16.2023_10x_TM 0.5 dilution-pp | D24: Lake Quinsigamond | E24: Quinsigamond | F24: Aphanizomenon (50%), Dolichospermum (45%), Microcystis Debris (5%)
C25: Leesville Pond_9.16.2023_10x_TM 0.5 dilution-pp | D25: Leeseville Pond | E25: Leesville | F25: none
C26: Little Indian_9.16.2023_10x_TM 0.1 dilution-pp | D26: Little Indian Lake | E26: L.Indian | F26: Aphanizomenon (20%), Dolichospermum (75%), Microcystis (5%)
C27: Manchaug Pond_9.16.2023_10x_TM 0.5 dilution-pp | D27: Manchaug Pond | E27: Manchaug | F27: Dolichospermum (50%), Microcystis (50%)
C28: Newton Pond_9.16.2023_10x_TM 0.5 dilution-pp | D28: Newton Pond | E28: Newton | F28: none
C29: Patch Pond_9.16.2023_10x_TM 0.5 dilution-pp | D29: Patch Pond | E29: Patch.P | F29: Dolichospermum (100%)
C30: Patch Res_9.16.2023_10x_TM 0.5 dilution-pp | D30: Patch Reservoir | E30: Patch.R | F30: Dolichospermum (75%), Oscillatoria (20%), Woronichinia (5%)
C31: Salisbury Pond_9.16.2023_10x_TM 0.5 dilution | D31: Salisbury Pond | E31: Salisbury | F31: Microcystis Debris (100%)
C32: Salisbury Pond_9.16.2023_10x_TM 0.5 dilution-pp
D33: Singletary Lake | E33: Singletary | F33: NA
C34: Stevens Pond_9.16.2023_10x_TM 0.5 dilution-pp | D34: Stevens Pond | E34: Stevens | F34: Dolichospermum
C35: Lake Ellie_9.16.2023_10x_TM 0.1 dilution-pp | D35: Lake ellie | E35: Ellie | F35: none
